Workbook

Sheet Dataset Overview
A1: Messy Sales Dataset - Data Cleaning & Analysis Challenge
A3: This dataset has been intentionally generated with real-world data quality issues to simulate raw business data.
A4: As a data analyst, your goal is to clean, validate, transform, and analyze this data.
A6: Issue Category | B6: Description | C6: Examples in Dataset | D6: Analytical Impact
A7: Duplicates | B7: Repeated transaction IDs with identical or conflicting records. | C7: Multiple rows with 'TXN-1012' | D7: Overstates revenue and volume metrics if unhandled.
A8: Date Inconsistencies | B8: Mixed date formats, impossible dates, missing values. | C8: 2023-08-14, 03/22/2023, 2023-02-30, blank cells | D8: Breaks time-series aggregations, month-over-month analysis.
A9: Text Inconsistencies | B9: Mixed casing, leading/trailing whitespace, non-standard naming. | C9: 'North' vs ' north', 'Electronics' vs 'Elec.' | D9: Splits category/region groupings into duplicate buckets.
A10: Data Type Pollution | B10: Mixed string/numeric values in numeric fields. | C10: '5 pcs' or '$250.00' in quantity/price fields | D10: Causes errors during math calculations or database loads.
A11: Anomalies & Outliers | B11: Unrealistic numbers, negative quantities or prices. | C11: Units_Sold = 9999 or -5, Unit_Price = -150.00 | D11: Distorts mean, variance, and totals significantly.
A12: Mathematical Errors | B12: Total Amount does not match Units Sold * Unit Price. | C12: Total_Amount = $1,550.50 when 5 * $210 = $1,050 | D12: Lead to incorrect financial reporting to stakeholders.
A13: Invalid / Missing Data | B13: Malformed email formats and empty cells across attributes. | C13: 'invalid_email_at_gmail.com', missing regions/payments | D13: Impacts customer reachability analysis and completeness.

Sheet Raw_Sales_Data
A1: Transaction_ID | B1: Date | C1: Region | D1: Category | E1: Units_Sold | F1: Unit_Price | G1: Total_Amount | H1: Customer_Email | I1: Payment_Method
A2: TXN-1000 | B2: 2023-07-13 | C2: South | D2: Office Supplies | E2: 5 | F2: 387.29 | G2: 1936.45 | H2: user_0@company.com | I2: cc
A3: TXN-1001 | B3: 18-Nov-2023 | C3: north | D3: Office-Supplies | E3: 4 | F3: 60.94 | G3: 243.76 | H3: user_1@company.com | I3: CREDIT CARD
A4: TXN-1002 | B4: 2023-12-27 | C4: West | D4: Office Supplies | E4: 4 | F4: 481.56 | G4: 1926.24 | H4: user_2@company.com
A5: TXN-1003 | C5: EAST | D5: electronics | E5: 5 | F5: 446.21 | G5: 2231.05 | H5: user_3@company.com | I5: PayPal
A6: TXN-1004 | B6: 2023-05-29 | C6: NORTH | D6: Elec. | E6: 5 pcs | F6: 142.47 | G6: 712.35 | H6: user_4@company.com | I6: Credit Card
A7: TXN-1005 | B7: 2023/02/21 00:00 | C7: East | D7: Office-Supplies | E7: 3 | F7: 413.15 | G7: 1239.45 | H7: user_5@company.com | I7: Paypal
A8: TXN-1006 | B8: 22-Nov-2023 | C8: EAST | D8: Furniture | E8: 5 | F8: 263.98 | G8: 1319.9 | H8: user_6@company.com | I8: Paypal
A9: TXN-1007 | B9: 07/01/2023 | C9: East | D9: Furniture | E9: 4 | F9: 236.29 | G9: 945.16 | H9: user_7@company.com | I9: Paypal
A10: TXN-1008 | B10: 2023-12-26 | C10: NORTH | D10: Office-Supplies | E10: 6 | F10: 164.07 | G10: 984.42 | H10: user_8@company.com | I10: Debit
A11: TXN-1009 | B11: 03/29/2023 | C11: West | D11: Office Supplies | E11: 7 | F11: 294.67 | G11: 2062.69 | H11: user_9@company.com | I11: Debit
A12: TXN-1010 | B12: 14-Jul-2023 | C12: North | D12: Furniture | E12: 2 | F12: 367.65 | H12: user_10@company.com | I12: cc
A13: TXN-1011 | B13: 11/24/2023 | C13: South | D13: Office-Supplies | E13: 5 | F13: 211.36 | H13: user_11@company.com
A14: TXN-1012 | B14: 01/29/2023 | C14: West | D14: Furniture | E14: 5 | F14: 318.32 | G14: 1645.25 | H14: user_12@company.com | I14: Credit Card
A15: TXN-1013 | B15: 2023/06/11 00:00 | C15: West | D15: Office-Supplies | E15: 6 | F15: 352.66 | H15: invalid_email_at_gmail.com | I15: Cash
A16: TXN-1014 | B16: 19-Apr-2023 | C16: South | D16: OFFICE SUPPLIES | E16: 4 | F16: 358.45 | G16: 1433.8 | H16: user_14@company.com | I16: cc
A17: TXN-1015 | B17: 2023/09/13 00:00 | C17: South | D17: Elec. | E17: 6 | F17: 35.46 | G17: 212.76 | H17: user_15@company.com | I17: Paypal
A18: TXN-1016 | B18: 2023/11/26 00:00 | C18: South | D18: Office Supplies | E18: 6 | F18: 431.28 | G18: 2587.68 | H18: invalid_email_at_gmail.com | I18: Debit
A19: TXN-1017 | B19: 03/13/2023 | D19: OFFICE SUPPLIES | E19: 1 | F19: 234.54 | G19: 234.54 | H19: user_17@company.com | I19: cc
A20: TXN-1018 | B20: 03-Oct-2023 | C20: North | D20: Furniture | E20: 7 | F20: 138.58 | G20: 970.06 | H20: user_18@company.com | I20: Debit
A21: TXN-1019 | B21: 2023/08/08 00:00 | C21: NORTH | D21: Furniture | E21: 2 | F21: 128.46 | G21: 623.43 | H21: user_19@company.com | I21: cc
A22: TXN-1020 | B22: 2023/03/12 00:00 | C22: north | D22: Office Supplies | E22: 11 | F22: 246.68 | G22: 2713.48 | H22: user_20@company.com | I22: Debit
A23: TXN-1021 | B23: 31/11/2023 | C23: north | D23: Office-Supplies | E23: 4 | F23: 444.55 | G23: 1778.2 | H23: user_21@company.com | I23: Paypal
A24: TXN-1022 | C24: East | D24: Elec. | E24: 9999 | F24: 195.39 | G24: 586.17 | H24: user_22@company.com | I24: cc
A25: TXN-1023 | B25: 11/18/2023 | C25: West | D25: electronics | E25: 8 | F25: 377.37 | G25: 3018.96 | H25: user_23@company.com
A26: TXN-1024 | B26: 2023-08-05 | C26: EAST | D26: Furniture | E26: 3 | F26: 57.44 | G26: 172.32 | H26: user_24@company.com | I26: Paypal
A27: TXN-1025 | B27: 2023/11/02 00:00 | D27: OFFICE SUPPLIES | E27: 3 | F27: 243.27 | G27: 729.81 | H27: user_25@company.com | I27: Debit
A28: TXN-1026 | B28: 2023-10-11 | C28: South | D28: Elec. | E28: 5 | F28: 495.93 | H28: invalid_email_at_gmail.com | I28: PayPal
A29: TXN-1027 | B29: 28-Feb-2023 | C29: West | D29: electronics | E29: 8 | F29: 387.51 | G29: 3100.08 | H29: user_27@company.com | I29: Credit Card
A30: TXN-1028 | B30: 2023-06-24 | C30: North | D30: Furniture | E30: 3 | F30: 113.16 | G30: 339.48 | H30: user_28@company.com | I30: CASH
A31: TXN-1029 | B31: 2023/03/22 00:00 | C31: EAST | D31: Office-Supplies | E31: 2 | F31: 255.71 | G31: 511.42 | H31: user_29@company.com | I31: cc
A32: TXN-1030 | C32: West | D32: Office Supplies | E32: 5 pcs | F32: 124.48 | G32: 622.4 | H32: user_at_company | I32: Debit
A33: TXN-1031 | B33: 05/15/2023 | C33: EAST | D33: Electronics | E33: 5 pcs | F33: 210.68 | G33: 632.04 | H33: user_at_company | I33: Paypal
A34: TXN-1032 | B34: 24-Feb-2023 | C34: West | D34: Elec. | E34: 8 | F34: 392.24 | G34: 3137.92 | H34: user_32@company.com | I34: Debit
A35: TXN-1033 | B35: 09/17/2023 | C35: West | D35: Office-Supplies | E35: 10 | F35: 387.9 | G35: 3879 | H35: user_33@company.com | I35: Credit Card
A36: TXN-1034 | B36: 2023-03-24 | D36: Electronics | E36: 3 | F36: 121.77 | G36: 365.31 | H36: user_34@company.com | I36: PayPal
A37: TXN-1035 | B37: 2023-09-08 | C37: South | D37: electronics | E37: 2 | F37: 461.89 | G37: 923.78 | H37: user_35@company.com | I37: CASH
A38: TXN-1036 | B38: 05-Jul-2023 | C38: West | D38: Elec. | E38: 5 | F38: 300.36 | G38: 1501.8 | H38: user_36@company.com | I38: PayPal
A39: TXN-1037 | B39: 2023-05-04 | C39: South | D39: OFFICE SUPPLIES | E39: 7 | F39: 196.16 | G39: 1373.12 | H39: user_37@company.com | I39: Debit
A40: TXN-1038 | B40: 31/11/2023 | C40: north | D40: Office-Supplies | E40: 6 | F40: 255.95 | G40: 1535.7 | H40: user_38@company.com | I40: CREDIT CARD
...

Sheet messy_sales_dataset
A1: Transaction_ID | B1: Date | C1: Region | D1: Category | E1: Units_Sold | F1: Unit_Price | G1: Total_Amount | H1: Customer_Email | I1: Payment_Method
A2: TXN-1000 | B2: 2023-07-13 | C2: =PROPER(Raw_Sales_Data!C2) -> South | D2: Office Supplies | E2: 5 | F2: 387.29 | G2: 1936.45 | H2: user_0@company.com | I2: cc
A3: TXN-1001 | B3: 18-Nov-2023 | C3: =PROPER(Raw_Sales_Data!C3) -> North | D3: Office Supplies | E3: 4 | F3: 60.94 | G3: 243.76 | H3: user_1@company.com | I3: CREDIT CARD
A4: TXN-1002 | B4: 2023-12-27 | C4: =PROPER(Raw_Sales_Data!C4) -> West | D4: Office Supplies | E4: 4 | F4: 481.56 | G4: 1926.24 | H4: user_2@company.com
A5: TXN-1003 | C5: =PROPER(Raw_Sales_Data!C5) -> East | D5: Electronics | E5: 5 | F5: 446.21 | G5: 2231.05 | H5: user_3@company.com | I5: PayPal
A6: TXN-1004 | B6: 2023-05-29 | C6: =PROPER(Raw_Sales_Data!C6) -> North | D6: Electronics | E6: 5 | F6: 142.47 | G6: 712.35 | H6: user_4@company.com | I6: Credit Card
A7: TXN-1005 | B7: 2023/02/21 00:00 | C7: =PROPER(Raw_Sales_Data!C7) -> East | D7: Office Supplies | E7: 3 | F7: 413.15 | G7: 1239.45 | H7: user_5@company.com | I7: Paypal
A8: TXN-1006 | B8: 22-Nov-2023 | C8: =PROPER(Raw_Sales_Data!C8) -> East | D8: Furniture | E8: 5 | F8: 263.98 | G8: 1319.9 | H8: user_6@company.com | I8: Paypal
A9: TXN-1007 | B9: 07/01/2023 | C9: =PROPER(Raw_Sales_Data!C9) -> East | D9: Furniture | E9: 4 | F9: 236.29 | G9: 945.16 | H9: user_7@company.com | I9: Paypal
A10: TXN-1008 | B10: 2023-12-26 | C10: =PROPER(Raw_Sales_Data!C10) -> North | D10: Office Supplies | E10: 6 | F10: 164.07 | G10: 984.42 | H10: user_8@company.com | I10: Debit
A11: TXN-1009 | B11: 03/29/2023 | C11: =PROPER(Raw_Sales_Data!C11) -> West | D11: Office Supplies | E11: 7 | F11: 294.67 | G11: 2062.69 | H11: user_9@company.com | I11: Debit
A12: TXN-1010 | B12: 14-Jul-2023 | C12: =PROPER(Raw_Sales_Data!C12) -> North | D12: Furniture | E12: 2 | F12: 367.65 | H12: user_10@company.com | I12: cc
A13: TXN-1011 | B13: 11/24/2023 | C13: =PROPER(Raw_Sales_Data!C13) -> South | D13: Office Supplies | E13: 5 | F13: 211.36 | H13: user_11@company.com
A14: TXN-1012 | B14: 01/29/2023 | C14: =PROPER(Raw_Sales_Data!C14) -> West | D14: Furniture | E14: 5 | F14: 318.32 | G14: 1645.25 | H14: user_12@company.com | I14: Credit Card
A15: TXN-1013 | B15: 2023/06/11 00:00 | C15: =PROPER(Raw_Sales_Data!C15) -> West | D15: Office Supplies | E15: 6 | F15: 352.66 | H15: invalid_email_at_gmail.com | I15: Cash
A16: TXN-1014 | B16: 19-Apr-2023 | C16: =PROPER(Raw_Sales_Data!C16) -> South | D16: Office Supplies | E16: 4 | F16: 358.45 | G16: 1433.8 | H16: user_14@company.com | I16: cc
A17: TXN-1015 | B17: 2023/09/13 00:00 | C17: =PROPER(Raw_Sales_Data!C17) -> South | D17: Electronics | E17: 6 | F17: 35.46 | G17: 212.76 | H17: user_15@company.com | I17: Paypal
A18: TXN-1016 | B18: 2023/11/26 00:00 | C18: =PROPER(Raw_Sales_Data!C18) -> South | D18: Office Supplies | E18: 6 | F18: 431.28 | G18: 2587.68 | H18: invalid_email_at_gmail.com | I18: Debit
A19: TXN-1017 | B19: 03/13/2023 | C19: =PROPER(Raw_Sales_Data!C19) | D19: Office Supplies | E19: 1 | F19: 234.54 | G19: 234.54 | H19: user_17@company.com | I19: cc
A20: TXN-1018 | B20: 03-Oct-2023 | C20: =PROPER(Raw_Sales_Data!C20) -> North | D20: Furniture | E20: 7 | F20: 138.58 | G20: 970.06 | H20: user_18@company.com | I20: Debit
A21: TXN-1019 | B21: 2023/08/08 00:00 | C21: =PROPER(Raw_Sales_Data!C21) -> North | D21: Furniture | E21: 2 | F21: 128.46 | G21: 623.43 | H21: user_19@company.com | I21: cc
A22: TXN-1020 | B22: 2023/03/12 00:00 | C22: =PROPER(Raw_Sales_Data!C22) -> North | D22: Office Supplies | E22: 11 | F22: 246.68 | G22: 2713.48 | H22: user_20@company.com | I22: Debit
A23: TXN-1021 | B23: 31/11/2023 | C23: =PROPER(Raw_Sales_Data!C23) -> North | D23: Office Supplies | E23: 4 | F23: 444.55 | G23: 1778.2 | H23: user_21@company.com | I23: Paypal
A24: TXN-1022 | C24: =PROPER(Raw_Sales_Data!C24) -> East | D24: Electronics | E24: 9999 | F24: 195.39 | G24: 586.17 | H24: user_22@company.com | I24: cc
A25: TXN-1023 | B25: 11/18/2023 | C25: =PROPER(Raw_Sales_Data!C25) -> West | D25: Electronics | E25: 8 | F25: 377.37 | G25: 3018.96 | H25: user_23@company.com
A26: TXN-1024 | B26: 2023-08-05 | C26: =PROPER(Raw_Sales_Data!C26) -> East | D26: Furniture | E26: 3 | F26: 57.44 | G26: 172.32 | H26: user_24@company.com | I26: Paypal
A27: TXN-1025 | B27: 2023/11/02 00:00 | C27: =PROPER(Raw_Sales_Data!C27) | D27: Office Supplies | E27: 3 | F27: 243.27 | G27: 729.81 | H27: user_25@company.com | I27: Debit
A28: TXN-1026 | B28: 2023-10-11 | C28: =PROPER(Raw_Sales_Data!C28) -> South | D28: Electronics | E28: 5 | F28: 495.93 | H28: invalid_email_at_gmail.com | I28: PayPal
A29: TXN-1027 | B29: 28-Feb-2023 | C29: =PROPER(Raw_Sales_Data!C29) -> West | D29: Electronics | E29: 8 | F29: 387.51 | G29: 3100.08 | H29: user_27@company.com | I29: Credit Card
A30: TXN-1028 | B30: 2023-06-24 | C30: =PROPER(Raw_Sales_Data!C30) -> North | D30: Furniture | E30: 3 | F30: 113.16 | G30: 339.48 | H30: user_28@company.com | I30: CASH
A31: TXN-1029 | B31: 2023/03/22 00:00 | C31: =PROPER(Raw_Sales_Data!C31) -> East | D31: Office Supplies | E31: 2 | F31: 255.71 | G31: 511.42 | H31: user_29@company.com | I31: cc
A32: TXN-1030 | C32: =PROPER(Raw_Sales_Data!C32) -> West | D32: Office Supplies | E32: 5 | F32: 124.48 | G32: 622.4 | H32: user_at_company | I32: Debit
A33: TXN-1031 | B33: 05/15/2023 | C33: =PROPER(Raw_Sales_Data!C33) -> East | D33: Electronics | E33: 5 | F33: 210.68 | G33: 632.04 | H33: user_at_company | I33: Paypal
A34: TXN-1032 | B34: 24-Feb-2023 | C34: =PROPER(Raw_Sales_Data!C34) -> West | D34: Electronics | E34: 8 | F34: 392.24 | G34: 3137.92 | H34: user_32@company.com | I34: Debit
A35: TXN-1033 | B35: 09/17/2023 | C35: =PROPER(Raw_Sales_Data!C35) -> West | D35: Office Supplies | E35: 10 | F35: 387.9 | G35: 3879 | H35: user_33@company.com | I35: Credit Card
A36: TXN-1034 | B36: 2023-03-24 | C36: =PROPER(Raw_Sales_Data!C36) | D36: Electronics | E36: 3 | F36: 121.77 | G36: 365.31 | H36: user_34@company.com | I36: PayPal
A37: TXN-1035 | B37: 2023-09-08 | C37: =PROPER(Raw_Sales_Data!C37) -> South | D37: Electronics | E37: 2 | F37: 461.89 | G37: 923.78 | H37: user_35@company.com | I37: CASH
A38: TXN-1036 | B38: 05-Jul-2023 | C38: =PROPER(Raw_Sales_Data!C38) -> West | D38: Electronics | E38: 5 | F38: 300.36 | G38: 1501.8 | H38: user_36@company.com | I38: PayPal
A39: TXN-1037 | B39: 2023-05-04 | C39: =PROPER(Raw_Sales_Data!C39) -> South | D39: Office Supplies | E39: 7 | F39: 196.16 | G39: 1373.12 | H39: user_37@company.com | I39: Debit
A40: TXN-1038 | B40: 31/11/2023 | C40: =PROPER(Raw_Sales_Data!C40) -> North | D40: Office Supplies | E40: 6 | F40: 255.95 | G40: 1535.7 | H40: user_38@company.com | I40: CREDIT CARD
...
